Workbook

Sheet Query
B1: Query to collect all data
B3: Query 1 | C3: Query 2 | D3: Query 3 | E3: Query 4
B4: SELECT ident.id, basic.otype, basic.ra, basic.dec, mesDistance.dist, mesDistance.unit, allfluxes.V, basic.oid FROM basic JOIN ident ON basic.oid = ident.oidref LEFT JOIN mesDistance ON basic.oid = mesDistance.oidref LEFT JOIN allfluxes ON basic.oid = allfluxes.oidref WHERE ident.id IN ('Laniakea Supercluster', 'Virgo Supercluster', 'Local Group', 'Milky Way Group', 'Large Magellanic Cloud', 'Small Magellanic Cloud', 'Sgr Dwarf Galaxy', 'Sculptor Dwarf Galaxy', 'Canis Major Dwarf Galaxy', 'Fornax Dwarf Galaxy', 'Draco Dwarf Galaxy', 'Carina Dwarf Galaxy', 'Phoenix Dwarf Galaxy', 'UMi Galaxy', 'Hercules Dwarf Galaxy', 'Sextans Dwarf Galaxy', 'Pisces I', 'Pisces II', 'Coma Dwarf Galaxy', 'UMa I Galaxy', 'UMa II Galaxy', 'CVn I dSph', 'CVn II dSph', 'Leo I Dwarf Galaxy', 'Leo II Dwarf Galaxy', 'Leo IV Dwarf Galaxy', 'Leo V', 'Leo T Dwarf', 'Bootes I', 'Bootes II', 'Bootes III', 'Segue 2', 'Andromeda Group', 'Andromeda Galaxy', 'Triangulum Galaxy', 'M 32', 'M 110', 'NGC 185', 'NGC 147', 'Pegasus Dwarf', 'Andromeda I', 'Andromeda II', 'Andromeda III', 'Andromeda V', 'Pegasus Dwarf Galaxy', 'Cassiopeia Dwarf Galaxy', 'Andromeda IX', 'Andromeda X', 'Andromeda XI', 'Andromeda XII', 'Pisces III', 'Pisces IV', 'Andromeda XV', 'Pisces V', 'Andromeda XVII', 'Andromeda XVIII', 'Andromeda XIX', 'Andromeda XX', 'Andromeda XXI', 'Andromeda XXII', 'Andromeda XXIII', 'Andromeda XXIV', 'Andromeda XXV', 'Andromeda XXVI', 'Andromeda XXVII', 'Andromeda XXVIII', 'Andromeda XXIX', 'Cassiopeia II', 'Andromeda XXXI', 'Cassiopeia III', 'Perseus I Dwarf Galaxy', 'NGC 3109 Group', 'NGC 3109', 'Sextans A', 'Sextans B', 'Antlia Dwarf Galaxy', 'Barnard''s Galaxy', 'Aquarius Dwarf Galaxy', 'Cetus Dwarf Galaxy', 'IC 1613', 'Wolf-Lundmark-Melotte', 'Sag dIG', 'Leo A', 'Tucana Dwarf Galaxy', 'Maffei Group', 'Cam A', 'Cam B', 'LEDA 95594', 'Cas 1', 'Cas 2', 'IC 342', 'LEDA 166077', 'NGC 1560', 'NGC 1569', 'UGC 2773', 'UGCA 86', 'UGCA 92', 'UGCA 105', 'Mailyan 16', 'Dwingeloo 1', 'Dwingeloo 2', 'LEDA 2807103', 'LEDA 168300', 'LEDA 2807107', 'Maffei 1', 'Maffei 2', 'LEDA 166068', 'LEDA 3097825', 'LEDA 166069', 'Sculptor Group', 'NGC 253', 'NGC 55', 'NGC 300', 'NGC 247', 'NGC 7793', 'IC 5152', 'NGC 625', 'LEDA 6430', 'NGC 59', 'UGCA 442', 'UGCA 438', 'LEDA 1038', 'LEDA 72675', 'IC 1574', 'UGCA 15', 'LEDA 621', 'LEDA 1641', 'LEDA 2881', 'LEDA 2933', 'Sculptor dE1', 'LEDA 69468', 'M81 Group', 'M 81', 'NGC 2403', 'NGC 4236', 'IC 2574', 'M 82', 'NGC 2366', 'UGC 4305', 'NGC 2976', 'NGC 3077', 'NGC 4605', 'UGC 5139', 'NGC 5204', 'NGC 3738', 'UGC 5336', 'UGC 5692', 'UGC 5918', 'UGC 8201', 'UGCA 133', 'LEDA 23521', 'LEDA 30664', 'UGC 3794', 'UGC 4459', 'UGC 4483', 'UGC 4945', 'UGC 5423', 'UGC 5428', 'UGC 5442', 'UGC 6456', 'UGCA 220', 'NGC 4144', 'IKN', 'NGC 4068', 'F8D1', 'LEDA 166101', 'LEDA 28759', 'NGC 2537', 'UGC 4426', 'UGC 8508', 'UGC 7242', 'UGC 6541', 'LEDA 4689216', 'LEDA 28731', 'VKN', 'LEDA 31286', 'UGC 7298', 'LEDA 3097828', 'LEDA 29231', 'UGCA 281', 'LEDA 2807133', 'LEDA 166115', 'LEDA 50911', 'LEDA 28529', 'LEDA 32667', '[KKH2001] 79', 'LEDA 29167', 'HIJASS J1021+68', 'M 83 Group', 'NGC 5128 Group', 'LEDA 2815820', 'Cen N', 'Centaurus A', 'LEDA 166158', 'LEDA 2815824', 'LEDA 592761', 'LEDA 4614882', 'LEDA 3097113', 'LEDA 2815819', 'LEDA 559349', 'LEDA 2815823', 'LEDA 166152', 'LEDA 166167', 'LEDA 166172', 'LEDA 166175', 'LEDA 166179', 'NGC 4945', 'NGC 5102', 'NGC 5206', 'NGC 5237', 'LEDA 45104', 'LEDA 45717', 'LEDA 45916', 'LEDA 46663', 'LEDA 46680', 'LEDA 47171', 'LEDA 48515', 'LEDA 48738', 'LEDA 49615', 'AM 1321-304', 'LEDA 2815821', 'LEDA 166176', 'HIDEEP J1336-3321', 'IC 4247', 'IC 4316', 'LEDA 166170', 'LEDA 166163', 'LEDA 166164', 'M 83', 'NGC 5253', 'NGC 5264', 'LEDA 47885', 'LEDA 48111', 'UGCA 365', 'Canes Venatici Cloud', 'IC 3687', 'IC 4182', 'M 94', 'NGC 4190', 'NGC 4214', 'NGC 4244', 'NGC 4395', 'NGC 4449', 'UGC 6817', 'UGC 7559', 'UGC 7577', 'UGC 7698', 'UGC 8320', 'NGC 4631 Group', 'NGC 4631', 'NGC 4656', 'NGC 4657', 'NGC 4627', 'Leo I Group', 'M 96 Group', 'M 95', 'M 96', 'M 105', 'NGC 3299', 'NGC 3377', 'NGC 3384', 'NGC 3412', 'NGC 3489', 'M 66 Group', 'M 65', 'M 66', 'NGC 3628', 'Dorado Group', 'IC 2056', 'NGC 1543', 'NGC 1574', 'NGC 1533', 'NGC 1546', 'NGC 1553', 'NGC 1549', 'NGC 1566', 'NGC 1617', 'NGC 1515', 'NGC 1705', 'NGC 1596', 'IC 2049', 'NGC 1536', 'LEDA 390135', 'IC 2038', 'LEDA 75146', 'IC 2058', 'IC 2032', 'NGC 1602', 'NGC 1522', 'ESO 118-19', 'ESO 157-30', 'ESO 157-47', 'ESO 157-49', 'IC 2085', 'NGC 1581', 'ACO 3202', 'Fornax Cluster', 'ESO 357-7', 'ESO 357-12', 'IC 1913', 'NGC 1310', 'LEDA 12625', 'NGC 1316', 'NGC 1317', 'NGC 1326', 'NGC 1326A', 'NGC 1326B', 'IC 1919', 'NGC 1336', 'NGC 1341', 'NGC 1339', 'NGC 1344', 'ESO 358-9', 'ESO 358-10', 'NGC 1351', 'NGC 1350', 'NGC 1365', 'NGC 1366', 'NGC 1374', 'NGC 1375', 'IC 335', 'NGC 1379', 'NGC 1380', 'NGC 1381', 'NGC 1369', 'NGC 1386', 'NGC 1380A', 'NGC 1387', 'NGC 1382', 'NGC 1389', 'NGC 1396', 'NGC 1399', 'NGC 1404', 'NGC 1406', 'NGC 1427A', 'ESO 358-50', 'ESO 358-51', 'NGC 1425', 'NGC 1427', 'NGC 1428', 'NGC 1437A', 'NGC 1436', 'ESO 358-60', 'NGC 1437B', 'NGC 1460', 'LEDA 13809', 'IC 1993', 'ESO 302-9', 'ESO 302-14', 'ESO 359-3', 'NGC 1484', 'IC 2006', 'NGC 1531', 'NGC 1532', 'Virgo Cluster', 'NGC 4192', 'NGC 4216', 'NGC 4254', 'NGC 4303', 'NGC 4321', 'NGC 4365', 'NGC 4374', 'NGC 4382', 'NGC 4406', 'NGC 4429', 'NGC 4438', 'NGC 4442', 'NGC 4450', 'NGC 4459', 'NGC 4472', 'NGC 4473', 'NGC 4477', 'NGC 4486', 'NGC 4501', 'NGC 4526', 'NGC 4535', 'NGC 4548', 'NGC 4552', 'NGC 4569', 'NGC 4579', 'NGC 4596', 'NGC 4621', 'NGC 4654', 'NGC 4649', 'NGC 4762', 'Leo II Group', 'NGC 3156', 'NGC 3165', 'NGC 3166', 'NGC 3169', 'NGC 3162', 'NGC 3177', 'NGC 3185', 'NGC 3187', 'NGC 3190', 'NGC 3193', 'UGC 5574', 'NGC 3213', 'NGC 3226', 'NGC 3227', 'UGC 5675', 'NGC 3245A', 'NGC 3245', 'NGC 3254', 'NGC 3265', 'NGC 3277', 'NGC 3338', 'UGC 5832', 'NGC 3346', 'NGC 3389', 'NGC 3370', 'UGC 5945', 'NGC 3443', 'NGC 3447', 'NGC 3454', 'NGC 3455', 'NGC 3457', 'NGC 3381', 'IC 2604', 'NGC 3395', 'NGC 3396', 'NGC 3424', 'NGC 3430', 'NGC 3442', 'NGC 3380', 'UGC 5921', 'NGC 3400', 'NGC 3414', 'NGC 3418', 'NGC 3451', 'NGC 3504', 'NGC 3512', 'UGC 6112', 'NGC 3501', 'NGC 3507', 'UGC 6171', 'NGC 3592', 'NGC 3607', 'NGC 3608', 'NGC 3626', 'NGC 3655', 'NGC 3659', 'NGC 3681', 'NGC 3684', 'NGC 3686', 'NGC 3691', 'NGC 3630', 'NGC 3640', 'NGC 3664', 'NGC 3755', 'UGC 6603', 'NGC 3813', 'NGC 3098', 'UGC 5633', 'UGC 5708', 'NGC 3279', 'NGC 3287', 'NGC 3294', 'NGC 3301', 'NGC 3365', 'NGC 3423', 'NGC 3437', 'NGC 3485', 'NGC 3495', 'NGC 3547', 'NGC 3596', 'NGC 3666', 'NGC 3705', 'NGC 3810', 'UGC 6670', 'Ursa Major Cluster', 'NGC 3631', 'NGC 3953', 'M 109', 'NGC 3726', 'NGC 3938', 'NGC 4051', 'Virgo III Cloud', 'NGC 5248', 'UGC 8575', 'UGC 8614', 'NGC 5300', 'NGC 5348', 'NGC 5356', 'NGC 5360', 'NGC 5363', 'NGC 5364', 'IC 976', 'NGC 5496', 'NGC 5506', 'NGC 5507', 'UGC 9057', 'NGC 5560', 'NGC 5566', 'NGC 5569', 'NGC 5574', 'NGC 5576', 'NGC 5577', 'UGC 9215', 'IC 1024', 'NGC 5636', 'NGC 5638', 'NGC 5668', 'UGC 9310', 'UGC 9380', 'NGC 5658', 'NGC 5690', 'NGC 5691', 'NGC 5692', 'NGC 5705', 'NGC 5713', 'NGC 5719', 'NGC 5725', 'NGC 5740', 'NGC 5746', 'NGC 5750', 'UGC 9299', 'UGC 9469', 'UGC 9482', 'IC 1066', 'IC 1067', 'IC 1070', 'NGC 5770', 'NGC 5774', 'NGC 5775', 'NGC 5813', 'NGC 5831', 'NGC 5846', 'NGC 5846A', 'NGC 5854', 'NGC 5864', 'NGC 5869', 'UGC 9746', 'UGC 9751', 'UGC 9760', 'IC 1014', 'NGC 5334', 'NGC 5470', 'NGC 5584', 'NGC 5645', 'NGC 5669', 'NGC 5701', 'NGC 5792', 'NGC 5806', 'NGC 5838', 'NGC 5921', 'UGC 9169', 'UGC 9500', 'Eridanus Cluster', 'NGC 1232', 'IC 1898', 'NGC 1258', 'NGC 1297', 'NGC 1300', 'NGC 1325', 'NGC 1325A', 'NGC 1332', 'NGC 1347', 'NGC 1353', 'IC 1952', 'IC 1953', 'NGC 1359', 'NGC 1371', 'NGC 1370', 'NGC 1377', 'NGC 1385', 'NGC 1383', 'NGC 1395', 'NGC 1398', 'NGC 1401', 'NGC 1400', 'NGC 1407', 'NGC 1415', 'IC 346', 'NGC 1426', 'NGC 1439', 'NGC 1440', 'NGC 1438', 'NGC 1452', 'ESO 549-18', 'ESO 482-46', 'NGC 1482', 'Hydra-Cen Supercluster', 'Centaurus Supercluster', 'ACO 3565', 'IC 4296', 'IC 4329 Group', 'IC 4329', 'NGC 5298', 'NGC 5291', 'NGC 5302', 'ACO 3581', 'IC 4374', 'Centaurus Cluster', 'NGC 4696', 'NGC 4709', 'NGC 4729', 'NGC 4730', 'NGC 4743', 'HYDRA SUPERCL', 'Hydra Cluster', 'NGC 3309', 'NGC 3311', 'Great Attractor', 'Norma Cluster', 'SCL 175', 'ACO 3656', 'ACO 3698', 'ACO 3742', 'NGC 7014', 'King Ghidorah Supercluster', 'Saraswati supercluster', 'Shapley Supercluster', 'Hercules Supercluster', 'Coma Supercluster', 'Coma Cluster', 'NGC 4889', 'NGC 4872', 'Leo Cluster', 'NGC 3842', 'NGC 3883', 'NGC 3884', 'Per-Psc Supercluster', 'ACO 262', 'ACO 347', 'Perseus Cluster', 'Sculptor Supercluster', 'Pisces-Cetus Supercluster', 'Columba Supercluster', 'LEO SUPERCL', 'NGC 3550', 'Ophiuchus Supercluster', 'Bootes A Supercluster', 'CrB Supercluster', 'Aquarius-Cetus Supercluster', 'Lepus Supercluster', 'PEGASUS-PISCES SUPERCL', 'CAELUM SUPERCL', 'Draco Supercluster', 'DRACO-URSA MAJORIS SUPERC', 'Fornax-Eridanus Supercluster', 'Grus Supercluster', 'Leo A Supercluster', 'Leo-Sextans Supercluster', 'LEO-VIRGO SUPERCL', 'MICROSCOPIUM SUPERCL', 'Pisces-Aries Supercluster', 'UMa Supercluster', 'VIRGO-COMA SUPERCL', 'Bootes Supercluster', 'SCl 48', 'SCl 49', 'Aquarius Supercluster', 'Aquarius B Supercluster', 'AQR-CAP SUPERCL'); | C4: SELECT ident.id, basic.otype, basic.ra, basic.dec, mesDistance.dist, mesDistance.unit, allfluxes.V, basic.oid FROM basic JOIN ident ON basic.oid = ident.oidref LEFT JOIN mesDistance ON basic.oid = mesDistance.oidref LEFT JOIN allfluxes ON basic.oid = allfluxes.oidref WHERE ident.id IN ('M 1', 'M 2', 'M 3', 'M 4', 'M 5', 'M 6', 'M 7', 'M 8', 'M 9', 'M 10', 'M 11', 'M 12', 'M 13', 'M 14', 'M 15', 'M 16', 'M 17', 'M 18', 'M 19', 'M 20', 'M 21', 'M 22', 'M 23', 'M 24', 'M 25', 'M 26', 'M 27', 'M 28', 'M 29', 'M 30', 'M 34', 'M 35', 'M 36', 'M 37', 'M 38', 'M 39', 'M 40', 'M 41', 'M 42', 'M 43', 'M 44', 'M 45', 'M 46', 'M 47', 'M 48', 'M 50', 'M 52', 'M 53', 'M 54', 'M 55', 'M 56', 'M 57', 'M 62', 'M 67', 'M 68', 'M 69', 'M 70', 'M 71', 'M 72', 'M 73', 'M 75', 'M 76', 'M 78', 'M 79', 'M 80', 'M 92', 'M 93', 'M 97', 'M 103', 'M 107', 'Proxima Centauri', 'Barnard''s star', 'Wolf 359', 'LAL 21185', 'GJ 65', 'V* UV Cet', 'Ross 154', 'Ross 248', '* eps Eri', 'Ross 128', 'V* EZ Aqr', '* 61 Cyg A', '* 61 Cyg B', '* eps Ind', '* tau Cet', 'GJ 725 A', 'GJ 725 B', 'Gmb 34', 'Lacaille 9352', 'G 51-15', 'V* YZ Cet', 'Sirius A', 'Sirius B', 'Canopus', '* alf Cen A', '* alf Cen B', 'Arcturus', 'Vega', 'Capella', 'Rigel', 'Procyon A', 'Procyon B', 'Betelgeuse', 'Achernar', 'Hadar', 'Altair', 'Acrux', 'Aldebaran', 'Spica', 'Antares', 'Pollux', 'Fomalhaut', 'Mimosa', 'Deneb', 'Regulus', 'Adhara', 'Castor', 'Gacrux', 'Shaula', 'Bellatrix', 'Elnath', 'Miaplacidus', 'Alnilam', 'Alnair', 'Alnitak', '* gam Vel', 'Alioth', 'Mirfak', 'Kaus Australis', 'Dubhe', 'Wezen', 'Alkaid', 'Avior', 'Sargas', 'Menkalinan', 'Atria', 'Alhena', 'Alsephina', 'Peacock', 'Polaris', 'Mirzam', 'Alphard', 'Hamal', 'Algieba', 'Diphda', 'Nunki', 'Menkent', 'Alpheratz', 'Saiph', 'Mirach', 'Kochab', 'Tiaki', 'Rasalhague', 'Algol', 'Almach', 'Denebola', '* gam Cas', 'Muliphein', 'Naos', 'Aspidiske', 'Alphecca', 'Suhail', 'Mizar', 'Sadr', 'Schedar', 'Eltanin', 'Mintaka', 'Caph', '* eps Cen', 'Dschubba', 'Larawag', '* alf Lup', '* eta Cen', 'Merak', 'Izar', 'Enif', '* kap Sco', 'Ankaa', 'Phecda', 'Sabik', 'Scheat', 'Alderamin', 'Aludra', 'Markeb', 'Aljanah', 'Markab', 'Menkar', '* zet Oph', '* zet Cen', 'Zosma', '* bet Sco', 'Arneb', '* del Cen', '* gam Crv', 'V* UY Sct', 'M 51', 'M 63', 'M 64', 'M 74', 'M 77', 'M 101', 'M 102', 'M 104', 'M 106', 'M 108'); | D4: SELECT ident.id, basic.otype, basic.ra, basic.dec, mesDistance.dist, mesDistance.unit, allfluxes.V, basic.oid FROM basic JOIN ident ON basic.oid = ident.oidref LEFT JOIN mesDistance ON basic.oid = mesDistance.oidref LEFT JOIN allfluxes ON basic.oid = allfluxes.oidref WHERE ident.id IN ('IC1101'); | E4: SELECT ident.id, basic.otype, basic.ra, basic.dec, mesDistance.dist, mesDistance.unit, allfluxes.V, basic.oid FROM basic JOIN ident ON basic.oid = ident.oidref LEFT JOIN mesDistance ON basic.oid = mesDistance.oidref LEFT JOIN allfluxes ON basic.oid = allfluxes.oidref WHERE ident.id IN ('Luhman 16','CNS5 2194','LHS 1565');

Sheet ObjectStructure
B1: 1 | C1: 2 | D1: 3 | E1: 4 | F1: 5 | G1: 6 | H1: Simbad Name
B2: Laniakea-Superhaufen | H2: Laniakea Supercluster
C3: Virgo-Superhaufen | H3: Virgo Supercluster
D4: Lokale Gruppe | H4: Local Group
E5: Milky Way Group | H5: Milky Way Group
G6: M 1 | H6: M 1
G7: M 2 | H7: M 2
G8: M 3 | H8: M 3
G9: M 4 | H9: M 4
G10: M 5 | H10: M 5
G11: M 6 | H11: M 6
G12: M 7 | H12: M 7
G13: M 8 | H13: M 8
G14: M 9 | H14: M 9
G15: M 10 | H15: M 10
G16: M 11 | H16: M 11
G17: M 12 | H17: M 12
... G75: M 107 | H75: M 107
G76: Proxima Centauri | H76: Proxima Centauri | I76: https://en.wikipedia.org/wiki/List_of_nearest_stars
G77: Barnards Star | H77: Barnard''s star | I77: https://en.wikipedia.org/wiki/List_of_nearest_stars
G78: Wolf 359 | H78: Wolf 359 | I78: https://en.wikipedia.org/wiki/List_of_nearest_stars
G79: Lalande21185 | H79: LAL 21185 | I79: https://en.wikipedia.org/wiki/List_of_nearest_stars
G80: BL Ceti | H80: GJ 65 | I80: https://en.wikipedia.org/wiki/List_of_nearest_stars | M80: war GJ 65
G81: UV Ceti | H81: V* UV Cet | I81: https://en.wikipedia.org/wiki/List_of_nearest_stars
G82: Ross 154 | H82: Ross 154 | I82: https://en.wikipedia.org/wiki/List_of_nearest_stars
G83: Ross 248 | H83: Ross 248 | I83: https://en.wikipedia.org/wiki/List_of_nearest_stars
G84: Epsilon Eridani | H84: * eps Eri | I84: https://en.wikipedia.org/wiki/List_of_nearest_stars
G85: Ross 128 | H85: Ross 128 | I85: https://en.wikipedia.org/wiki/List_of_nearest_stars
G86: EZ Aquarii | H86: V* EZ Aqr | I86: https://en.wikipedia.org/wiki/List_of_nearest_stars
G87: 61 Cygni A | H87: * 61 Cyg A | I87: https://en.wikipedia.org/wiki/List_of_nearest_stars
G88: 61 Cygni B | H88: * 61 Cyg B | I88: https://en.wikipedia.org/wiki/List_of_nearest_stars
G89: Epsilon Indi | H89: * eps Ind | I89: https://en.wikipedia.org/wiki/List_of_nearest_stars
G90: Tau Ceti | H90: * tau Cet | I90: https://en.wikipedia.org/wiki/List_of_nearest_stars
G91: Gliese 725 A | H91: GJ 725 A | I91: https://en.wikipedia.org/wiki/List_of_nearest_stars | M91: war GJ 725 A
G92: Gliese 725 B | H92: GJ 725 B | I92: https://en.wikipedia.org/wiki/List_of_nearest_stars | M92: war GJ 725 B
G93: Groombridge 34 | H93: Gmb 34 | I93: https://en.wikipedia.org/wiki/List_of_nearest_stars
G94: Lacaille 9352 | H94: Lacaille 9352 | I94: https://en.wikipedia.org/wiki/List_of_nearest_stars
G95: G 51-15 | H95: G 51-15 | I95: https://en.wikipedia.org/wiki/List_of_nearest_stars
G96: YZ Ceti | H96: V* YZ Cet | I96: https://en.wikipedia.org/wiki/List_of_nearest_stars
G97: Sirius A | H97: Sirius A | I97: https://en.wikipedia.org/wiki/List_of_nearest_stars
...

Sheet Result Query 1
A1: id,otype,ra,dec,dist,unit,V,oid
A2: ACO 262,"ClG",28.21,36.14611111111111,,,,1580015
A3: ACO 347,"ClG",36.45833333333333,41.875,,,,26654
A4: ACO 3202,"ClG",60.05833333333333,-53.66,,,,3025978
A5: ACO 3565,"ClG",204.1625,-33.97166666666667,,,,2178312
A6: ACO 3581,"ClG",211.87416666666667,-27.017777777777777,,,,4488029
A7: ACO 3656,"GrG",299.7245833333333,-38.34527777777778,,,,2323517
A8: ACO 3698,"ClG",308.9916666666667,-25.276666666666667,,,,2398114
A9: ACO 3742,"ClG",316.67083333333335,-47.14833333333333,,,,3468556
A10: AM 1321-304,"GiC",201.15095999999997,-30.971809999999994,4.76,"Mpc ",,2144855
A11: AM 1321-304,"GiC",201.15095999999997,-30.971809999999994,4.76,"Mpc ",,2144855
A12: AM 1321-304,"GiC",201.15095999999997,-30.971809999999994,4.76,"Mpc ",,2144855
... A3488: [KKH2001] 79,"LSB",184.965,61.51833333333333,,,,503204

Sheet Result Query 2
A1: id,otype,ra,dec,dist,unit,V,oid
A2: * 61 Cyg A,"BY*",316.7247482895925,38.74941731943694,3.4965,"pc ",5.21,837
A3: * 61 Cyg A,"BY*",316.7247482895925,38.74941731943694,3.4972,"pc ",5.21,837
A4: * 61 Cyg A,"BY*",316.7247482895925,38.74941731943694,3.482,"pc ",5.21,837
A5: * 61 Cyg B,"PM*",316.7302660185276,38.74204403329556,3.4964,"pc ",6.03,676
A6: * 61 Cyg B,"PM*",316.7302660185276,38.74204403329556,3.4947,"pc ",6.03,676
A7: * 61 Cyg B,"PM*",316.7302660185276,38.74204403329556,3.503,"pc ",6.03,676
A8: * alf Cen A,"SB*",219.90205833170774,-60.83399268831004,,,0.01,3396054
A9: * alf Cen B,"PM*",219.89609628987276,-60.83752756558407,,,1.33,3396297
A10: * alf Lup,"bC*",220.4823157775,-47.38819874611111,,,2.286,3438793
A11: * bet Sco,"**",241.35929166666665,-19.80538888888889,,,2.5,2529096
A12: * del Cen,"Be*",182.08957348875,-50.722427392777774,163.0,"pc ",2.52,3282937
... A559: Wolf 359,"PM*",164.1205036259475,7.014723134801666,2.0,"pc ",13.507,1769389

Sheet Result Query 3
A1: id,otype,ra,dec,dist,unit,V,oid
A2: IC 1101,"rG",227.733751,5.744775,,,,2678165

Sheet Result Query 4
A1: id | B1: otype | C1: ra | D1: dec | E1: dist | F1: unit | G1: V | H1: oid
A2: CNS5 2194 | B2: BD* | C2: 133.81890825 | D2: -7.247048000000001 | H2: 8596164
A3: LHS 1565 | B3: PM* | C3: 53.998746505525006 | D3: -44.51270300849139 | E3: 3.6742 | F3: pc | G3: 13.07 | H3: 2984511
A4: LHS 1565 | B4: PM* | C4: 53.998746505525006 | D4: -44.51270300849139 | E4: 3.6732 | F4: pc | G4: 13.07 | H4: 2984511
A5: Luhman 16 | B5: ** | C5: 162.32881400000002 | D5: -53.319466000000006 | E5: 2 | F5: pc | G5: 16.2 | H5: 8048683

Sheet Objects_prepared
A1: id | B1: otype | C1: ra | D1: dec | E1: dist | F1: unit | G1: V | H1: oid | I1: distLj | J1: distLj_Mean | K1: distLj_dev | L1: 50% Check | N1: 1Mpc | O1: 3261563.8 | P1: Lj | R1: 1kpc | S1: 3261.5638 | T1: Lj | V1: 1pc | W1: 3.2615638 | X1: Lj
A2: ACO 262 | B2: ClG | C2: 28.21 | D2: 36.14611111111111 | E2: 200000000 | F2: Lj | H2: 1580015 | I2: =_xlfn.IFS(F2="Mpc",E2*$O$1,F2="kpc",E2*$S$1,F2="pc",E2*$W$1,F2="Lj",E2,E2="",0) -> 200000000 | J2: =AVERAGEIFS(I:I,A:A,A2) -> 200000000 | K2: =(I2/J2-1)*100 -> 0 | L2: =IF(K2>50,"Groesser50",IF(K2<-50,"Kleiner -50","OK")) -> OK | M2: https://de.wikipedia.org/wiki/Abell_262
A3: ACO 347 | B3: ClG | C3: 36.45833333333333 | D3: 41.875 | E3: 250000000 | F3: Lj | H3: 26654 | I3: =_xlfn.IFS(F3="Mpc",E3*$O$1,F3="kpc",E3*$S$1,F3="pc",E3*$W$1,F3="Lj",E3,E3="",0) -> 250000000 | J3: =AVERAGEIFS(I:I,A:A,A3) -> 250000000 | K3: =(I3/J3-1)*100 -> 0 | L3: =IF(K3>50,"Groesser50",IF(K3<-50,"Kleiner -50","OK")) -> OK | M3: https://www.spektrum.de/alias/wunder-des-weltalls/abell-347-in-andromeda/1926976
A4: ACO 3202 | B4: ClG | C4: 60.05833333333333 | D4: -53.66 | E4: 920000000 | F4: Lj | H4: 3025978 | I4: =_xlfn.IFS(F4="Mpc",E4*$O$1,F4="kpc",E4*$S$1,F4="pc",E4*$W$1,F4="Lj",E4,E4="",0) -> 920000000 | J4: =AVERAGEIFS(I:I,A:A,A4) -> 920000000 | K4: =(I4/J4-1)*100 -> 0 | L4: =IF(K4>50,"Groesser50",IF(K4<-50,"Kleiner -50","OK")) -> OK | M4: http://www.andromedagalaxie.de/html/superhaufen_horologium.htm
A5: ACO 3565 | B5: ClG | C5: 204.1625 | D5: -33.97166666666667 | E5: 161000000 | F5: Lj | H5: 2178312 | I5: =_xlfn.IFS(F5="Mpc",E5*$O$1,F5="kpc",E5*$S$1,F5="pc",E5*$W$1,F5="Lj",E5,E5="",0) -> 161000000 | J5: =AVERAGEIFS(I:I,A:A,A5) -> 161000000 | K5: =(I5/J5-1)*100 -> 0 | L5: =IF(K5>50,"Groesser50",IF(K5<-50,"Kleiner -50","OK")) -> OK | M5: https://de.wikipedia.org/wiki/IC_4296
A6: ACO 3581 | B6: ClG | C6: 211.87416666666667 | D6: -27.017777777777777 | E6: 278000000 | F6: Lj | H6: 4488029 | I6: =_xlfn.IFS(F6="Mpc",E6*$O$1,F6="kpc",E6*$S$1,F6="pc",E6*$W$1,F6="Lj",E6,E6="",0) -> 278000000 | J6: =AVERAGEIFS(I:I,A:A,A6) -> 278000000 | K6: =(I6/J6-1)*100 -> 0 | L6: =IF(K6>50,"Groesser50",IF(K6<-50,"Kleiner -50","OK")) -> OK | M6: https://de.wikipedia.org/wiki/IC_4374
A7: ACO 3656 | B7: GrG | C7: 299.7245833333333 | D7: -38.34527777777778 | E7: 269000000 | F7: Lj | H7: 2323517 | I7: =_xlfn.IFS(F7="Mpc",E7*$O$1,F7="kpc",E7*$S$1,F7="pc",E7*$W$1,F7="Lj",E7,E7="",0) -> 269000000 | J7: =AVERAGEIFS(I:I,A:A,A7) -> 269000000 | K7: =(I7/J7-1)*100 -> 0 | L7: =IF(K7>50,"Groesser50",IF(K7<-50,"Kleiner -50","OK")) -> OK | M7: https://de.wikipedia.org/wiki/IC_4931
A8: ACO 3698 | B8: ClG | C8: 308.9916666666667 | D8: -25.276666666666667 | E8: 264000000 | F8: Lj | H8: 2398114 | I8: =_xlfn.IFS(F8="Mpc",E8*$O$1,F8="kpc",E8*$S$1,F8="pc",E8*$W$1,F8="Lj",E8,E8="",0) -> 264000000 | J8: =AVERAGEIFS(I:I,A:A,A8) -> 264000000 | K8: =(I8/J8-1)*100 -> 0 | L8: =IF(K8>50,"Groesser50",IF(K8<-50,"Kleiner -50","OK")) -> OK | M8: https://de.wikipedia.org/wiki/NGC_6936
A9: ACO 3742 | B9: ClG | C9: 316.67083333333335 | D9: -47.14833333333333 | E9: 70 | F9: Mpc | H9: 3468556 | I9: =_xlfn.IFS(F9="Mpc",E9*$O$1,F9="kpc",E9*$S$1,F9="pc",E9*$W$1,F9="Lj",E9,E9="",0) -> 2.2830946e+08 | J9: =AVERAGEIFS(I:I,A:A,A9) -> 2.2830946e+08 | K9: =(I9/J9-1)*100 -> 0 | L9: =IF(K9>50,"Groesser50",IF(K9<-50,"Kleiner -50","OK")) -> OK | M9: https://simbad.u-strasbg.fr/simbad/sim-id?mescat.distance=on&Ident=%403468574&Name=ESO+286-49&submit=display+selected+measurements#lab_meas
A10: AM 1321-304 | B10: GiC | C10: 201.15095999999997 | D10: -30.971809999999994 | E10: 4.76 | F10: Mpc | H10: 2144855 | I10: =_xlfn.IFS(F10="Mpc",E10*$O$1,F10="kpc",E10*$S$1,F10="pc",E10*$W$1,F10="Lj",E10,E10="",0) -> 15525044 | J10: =AVERAGEIFS(I:I,A:A,A10) -> 15519608 | K10: =(I10/J10-1)*100 -> 0.03502627 | L10: =IF(K10>50,"Groesser50",IF(K10<-50,"Kleiner -50","OK")) -> OK
A11: AM 1321-304 | B11: GiC | C11: 201.15095999999997 | D11: -30.971809999999994 | E11: 4.76 | F11: Mpc | H11: 2144855 | I11: =_xlfn.IFS(F11="Mpc",E11*$O$1,F11="kpc",E11*$S$1,F11="pc",E11*$W$1,F11="Lj",E11,E11="",0) -> 15525044 | J11: =AVERAGEIFS(I:I,A:A,A11) -> 15519608 | K11: =(I11/J11-1)*100 -> 0.03502627 | L11: =IF(K11>50,"Groesser50",IF(K11<-50,"Kleiner -50","OK")) -> OK
A12: AM 1321-304 | B12: GiC | C12: 201.15095999999997 | D12: -30.971809999999994 | E12: 4.76 | F12: Mpc | H12: 2144855 | I12: =_xlfn.IFS(F12="Mpc",E12*$O$1,F12="kpc",E12*$S$1,F12="pc",E12*$W$1,F12="Lj",E12,E12="",0) -> 15525044 | J12: =AVERAGEIFS(I:I,A:A,A12) -> 15519608 | K12: =(I12/J12-1)*100 -> 0.03502627 | L12: =IF(K12>50,"Groesser50",IF(K12<-50,"Kleiner -50","OK")) -> OK
A13: AM 1321-304 | B13: GiC | C13: 201.15095999999997 | D13: -30.971809999999994 | E13: 4.76 | F13: Mpc | H13: 2144855 | I13: =_xlfn.IFS(F13="Mpc",E13*$O$1,F13="kpc",E13*$S$1,F13="pc",E13*$W$1,F13="Lj",E13,E13="",0) -> 15525044 | J13: =AVERAGEIFS(I:I,A:A,A13) -> 15519608 | K13: =(I13/J13-1)*100 -> 0.03502627 | L13: =IF(K13>50,"Groesser50",IF(K13<-50,"Kleiner -50","OK")) -> OK
A14: AM 1321-304 | B14: GiC | C14: 201.15095999999997 | D14: -30.971809999999994 | E14: 4.88 | F14: Mpc | H14: 2144855 | I14: =_xlfn.IFS(F14="Mpc",E14*$O$1,F14="kpc",E14*$S$1,F14="pc",E14*$W$1,F14="Lj",E14,E14="",0) -> 15916431 | J14: =AVERAGEIFS(I:I,A:A,A14) -> 15519608 | K14: =(I14/J14-1)*100 -> 2.5569177 | L14: =IF(K14>50,"Groesser50",IF(K14<-50,"Kleiner -50","OK")) -> OK
A15: AM 1321-304 | B15: GiC | C15: 201.15095999999997 | D15: -30.971809999999994 | E15: 4.63 | F15: Mpc | H15: 2144855 | I15: =_xlfn.IFS(F15="Mpc",E15*$O$1,F15="kpc",E15*$S$1,F15="pc",E15*$W$1,F15="Lj",E15,E15="",0) -> 15101040 | J15: =AVERAGEIFS(I:I,A:A,A15) -> 15519608 | K15: =(I15/J15-1)*100 -> -2.6970228 | L15: =IF(K15>50,"Groesser50",IF(K15<-50,"Kleiner -50","OK")) -> OK
A16: Dwingeloo 1 | B16: GiG | C16: 44.21514973175001 | D16: 58.91170468878 | E16: 4.14 | F16: Mpc | H16: 211420 | I16: =_xlfn.IFS(F16="Mpc",E16*$O$1,F16="kpc",E16*$S$1,F16="pc",E16*$W$1,F16="Lj",E16,E16="",0) -> 13502874 | J16: =AVERAGEIFS(I:I,A:A,A16) -> 13502874 | K16: =(I16/J16-1)*100 -> 0 | L16: =IF(K16>50,"Groesser50",IF(K16<-50,"Kleiner -50","OK")) -> OK
A17: Dwingeloo 2 | B17: G | C17: 43.535291666666666 | D17: 59.00530555555556 | E17: 3.48 | F17: Mpc | H17: 210233 | I17: =_xlfn.IFS(F17="Mpc",E17*$O$1,F17="kpc",E17*$S$1,F17="pc",E17*$W$1,F17="Lj",E17,E17="",0) -> 11350242 | J17: =AVERAGEIFS(I:I,A:A,A17) -> 11350242 | K17: =(I17/J17-1)*100 -> 0 | L17: =IF(K17>50,"Groesser50",IF(K17<-50,"Kleiner -50","OK")) -> OK
A18: ESO 118-19 | B18: EmG | C18: 64.74794232692 | D18: -58.25753017908001 | G18: 15.51 | H18: 3038667 | I18: =_xlfn.IFS(F18="Mpc",E18*$O$1,F18="kpc",E18*$S$1,F18="pc",E18*$W$1,F18="Lj",E18,E18="",0) -> 0 | J18: =AVERAGEIFS(I:I,A:A,A18) -> 0 | K18: =(I18/J18-1)*100 -> #DIV/0! | L18: =IF(K18>50,"Groesser50",IF(K18<-50,"Kleiner -50","OK")) -> #DIV/0!
A19: ESO 157-30 | B19: GiG | C19: 66.88600968933 | D19: -54.19679156960999 | H19: 3024556 | I19: =_xlfn.IFS(F19="Mpc",E19*$O$1,F19="kpc",E19*$S$1,F19="pc",E19*$W$1,F19="Lj",E19,E19="",0) -> 0 | J19: =AVERAGEIFS(I:I,A:A,A19) -> 0 | K19: =(I19/J19-1)*100 -> #DIV/0! | L19: =IF(K19>50,"Groesser50",IF(K19<-50,"Kleiner -50","OK")) -> #DIV/0!
A20: ESO 157-47 | B20: AG? | C20: 69.82972 | D20: -54.21151 | E20: 21.491 | F20: Mpc | H20: 3011851 | I20: =_xlfn.IFS(F20="Mpc",E20*$O$1,F20="kpc",E20*$S$1,F20="pc",E20*$W$1,F20="Lj",E20,E20="",0) -> 70094267 | J20: =AVERAGEIFS(I:I,A:A,A20) -> 70094267 | K20: =(I20/J20-1)*100 -> 0 | L20: =IF(K20>50,"Groesser50",IF(K20<-50,"Kleiner -50","OK")) -> OK
A21: ESO 157-49 | B21: GiG | C21: 69.90367916666668 | D21: -53.01265 | E21: 19.32 | F21: Mpc | H21: 3012167 | I21: =_xlfn.IFS(F21="Mpc",E21*$O$1,F21="kpc",E21*$S$1,F21="pc",E21*$W$1,F21="Lj",E21,E21="",0) -> 63013412 | J21: =AVERAGEIFS(I:I,A:A,A21) -> 69777374 | K21: =(I21/J21-1)*100 -> -9.6936314 | L21: =IF(K21>50,"Groesser50",IF(K21<-50,"Kleiner -50","OK")) -> OK
A22: ESO 157-49 | B22: GiG | C22: 69.90367916666668 | D22: -53.01265 | E22: 23.6592 | F22: Mpc | H22: 3012167 | I22: =_xlfn.IFS(F22="Mpc",E22*$O$1,F22="kpc",E22*$S$1,F22="pc",E22*$W$1,F22="Lj",E22,E22="",0) -> 77165990 | J22: =AVERAGEIFS(I:I,A:A,A22) -> 69777374 | K22: =(I22/J22-1)*100 -> 10.588842 | L22: =IF(K22>50,"Groesser50",IF(K22<-50,"Kleiner -50","OK")) -> OK
A23: ESO 157-49 | B23: GiG | C23: 69.90367916666668 | D23: -53.01265 | E23: 23 | F23: Mpc | H23: 3012167 | I23: =_xlfn.IFS(F23="Mpc",E23*$O$1,F23="kpc",E23*$S$1,F23="pc",E23*$W$1,F23="Lj",E23,E23="",0) -> 75015967 | J23: =AVERAGEIFS(I:I,A:A,A23) -> 69777374 | K23: =(I23/J23-1)*100 -> 7.5075816 | L23: =IF(K23>50,"Groesser50",IF(K23<-50,"Kleiner -50","OK")) -> OK
A24: ESO 157-49 | B24: GiG | C24: 69.90367916666668 | D24: -53.01265 | E24: 18.62 | F24: Mpc | H24: 3012167 | I24: =_xlfn.IFS(F24="Mpc",E24*$O$1,F24="kpc",E24*$S$1,F24="pc",E24*$W$1,F24="Lj",E24,E24="",0) -> 60730318 | J24: =AVERAGEIFS(I:I,A:A,A24) -> 69777374 | K24: =(I24/J24-1)*100 -> -12.965601 | L24: =IF(K24>50,"Groesser50",IF(K24<-50,"Kleiner -50","OK")) -> OK
A25: ESO 157-49 | B25: GiG | C25: 69.90367916666668 | D25: -53.01265 | E25: 22.37 | F25: Mpc | H25: 3012167 | I25: =_xlfn.IFS(F25="Mpc",E25*$O$1,F25="kpc",E25*$S$1,F25="pc",E25*$W$1,F25="Lj",E25,E25="",0) -> 72961182 | J25: =AVERAGEIFS(I:I,A:A,A25) -> 69777374 | K25: =(I25/J25-1)*100 -> 4.5628087 | L25: =IF(K25>50,"Groesser50",IF(K25<-50,"Kleiner -50","OK")) -> OK
A26: ESO 302-14 | B26: GiG | C26: 57.92042000000001 | D26: -38.45222 | E26: 9.6 | F26: Mpc | H26: 687146 | I26: =_xlfn.IFS(F26="Mpc",E26*$O$1,F26="kpc",E26*$S$1,F26="pc",E26*$W$1,F26="Lj",E26,E26="",0) -> 31311012 | J26: =AVERAGEIFS(I:I,A:A,A26) -> 35877202 | K26: =(I26/J26-1)*100 -> -12.727273 | L26: =IF(K26>50,"Groesser50",IF(K26<-50,"Kleiner -50","OK")) -> OK
A27: ESO 302-14 | B27: GiG | C27: 57.92042000000001 | D27: -38.45222 | E27: 11.7 | F27: Mpc | H27: 687146 | I27: =_xlfn.IFS(F27="Mpc",E27*$O$1,F27="kpc",E27*$S$1,F27="pc",E27*$W$1,F27="Lj",E27,E27="",0) -> 38160296 | J27: =AVERAGEIFS(I:I,A:A,A27) -> 35877202 | K27: =(I27/J27-1)*100 -> 6.3636364 | L27: =IF(K27>50,"Groesser50",IF(K27<-50,"Kleiner -50","OK")) -> OK
A28: ESO 302-14 | B28: GiG | C28: 57.92042000000001 | D28: -38.45222 | E28: 11.7 | F28: Mpc | H28: 687146 | I28: =_xlfn.IFS(F28="Mpc",E28*$O$1,F28="kpc",E28*$S$1,F28="pc",E28*$W$1,F28="Lj",E28,E28="",0) -> 38160296 | J28: =AVERAGEIFS(I:I,A:A,A28) -> 35877202 | K28: =(I28/J28-1)*100 -> 6.3636364 | L28: =IF(K28>50,"Groesser50",IF(K28<-50,"Kleiner -50","OK")) -> OK
A29: ESO 302-9 | B29: EmG | C29: 56.89217 | D29: -38.57653 | E29: 21.98 | F29: Mpc | H29: 687144 | I29: =_xlfn.IFS(F29="Mpc",E29*$O$1,F29="kpc",E29*$S$1,F29="pc",E29*$W$1,F29="Lj",E29,E29="",0) -> 71689172 | J29: =AVERAGEIFS(I:I,A:A,A29) -> 60241083 | K29: =(I29/J29-1)*100 -> 19.00379 | L29: =IF(K29>50,"Groesser50",IF(K29<-50,"Kleiner -50","OK")) -> OK
A30: ESO 302-9 | B30: EmG | C30: 56.89217 | D30: -38.57653 | E30: 19.5 | F30: Mpc | H30: 687144 | I30: =_xlfn.IFS(F30="Mpc",E30*$O$1,F30="kpc",E30*$S$1,F30="pc",E30*$W$1,F30="Lj",E30,E30="",0) -> 63600494 | J30: =AVERAGEIFS(I:I,A:A,A30) -> 60241083 | K30: =(I30/J30-1)*100 -> 5.5766107 | L30: =IF(K30>50,"Groesser50",IF(K30<-50,"Kleiner -50","OK")) -> OK
A31: ESO 302-9 | B31: EmG | C31: 56.89217 | D31: -38.57653 | E31: 19 | F31: Mpc | H31: 687144 | I31: =_xlfn.IFS(F31="Mpc",E31*$O$1,F31="kpc",E31*$S$1,F31="pc",E31*$W$1,F31="Lj",E31,E31="",0) -> 61969712 | J31: =AVERAGEIFS(I:I,A:A,A31) -> 60241083 | K31: =(I31/J31-1)*100 -> 2.8695181 | L31: =IF(K31>50,"Groesser50",IF(K31<-50,"Kleiner -50","OK")) -> OK
... A43: ESO 357-7 | B43: EmG | C43: 47.5981078 | D43: -33.1535773 | E43: 15.3 | F43: Mpc | H43: 629108 | I43: =_xlfn.IFS(F43="Mpc",E43*$O$1,F43="kpc",E43*$S$1,F43="pc",E43*$W$1,F43="Lj",E43,E43="",0) -> 49901926 | J43: =AVERAGEIFS(I:I,A:A,A43) -> 53391799 | K43: =(I43/J43-1)*100 -> -6.536347 | L43: =IF(K43>50,"Groesser50",IF(K43<-50,"Kleiner -50","OK")) -> OK
A44: ESO 358-10 | B44: GiG | C44: 52.43027 | D44: -33.55694 | H44: 656175 | I44: =_xlfn.IFS(F44="Mpc",E44*$O$1,F44="kpc",E44*$S$1,F44="pc",E44*$W$1,F44="Lj",E44,E44="",0) -> 0 | J44: =AVERAGEIFS(I:I,A:A,A44) -> 0 | K44: =(I44/J44-1)*100 -> #DIV/0! | L44: =IF(K44>50,"Groesser50",IF(K44<-50,"Kleiner -50","OK")) -> #DIV/0!
A45: ESO 358-50 | B45: GiG | C45: 55.26503265065 | D45: -33.77924934877 | E45: 19.6789 | F45: Mpc | H45: 668170 | I45: =_xlfn.IFS(F45="Mpc",E45*$O$1,F45="kpc",E45*$S$1,F45="pc",E45*$W$1,F45="Lj",E45,E45="",0) -> 64183987 | J45: =AVERAGEIFS(I:I,A:A,A45) -> 61822044 | K45: =(I45/J45-1)*100 -> 3.8205513 | L45: =IF(K45>50,"Groesser50",IF(K45<-50,"Kleiner -50","OK")) -> OK
A46: ESO 358-50 | B46: GiG | C46: 55.26503265065 | D46: -33.77924934877 | E46: 19.77 | F46: Mpc | H46: 668170 | I46: =_xlfn.IFS(F46="Mpc",E46*$O$1,F46="kpc",E46*$S$1,F46="pc",E46*$W$1,F46="Lj",E46,E46="",0) -> 64481116 | J46: =AVERAGEIFS(I:I,A:A,A46) -> 61822044 | K46: =(I46/J46-1)*100 -> 4.3011703 | L46: =IF(K46>50,"Groesser50",IF(K46<-50,"Kleiner -50","OK")) -> OK
A47: ESO 358-50 | B47: GiG | C47: 55.26503265065 | D47: -33.77924934877 | E47: 19.77 | F47: Mpc | H47: 668170 | I47: =_xlfn.IFS(F47="Mpc",E47*$O$1,F47="kpc",E47*$S$1,F47="pc",E47*$W$1,F47="Lj",E47,E47="",0) -> 64481116 | J47: =AVERAGEIFS(I:I,A:A,A47) -> 61822044 | K47: =(I47/J47-1)*100 -> 4.3011703 | L47: =IF(K47>50,"Groesser50",IF(K47<-50,"Kleiner -50","OK")) -> OK
A48: ESO 358-50 | B48: GiG | C48: 55.26503265065 | D48: -33.77924934877 | E48: 16.6 | F48: Mpc | H48: 668170 | I48: =_xlfn.IFS(F48="Mpc",E48*$O$1,F48="kpc",E48*$S$1,F48="pc",E48*$W$1,F48="Lj",E48,E48="",0) -> 54141959 | J48: =AVERAGEIFS(I:I,A:A,A48) -> 61822044 | K48: =(I48/J48-1)*100 -> -12.422892 | L48: =IF(K48>50,"Groesser50",IF(K48<-50,"Kleiner -50","OK")) -> OK
A49: ESO 358-51 | B49: EmG | C49: 55.3858625 | D49: -34.888336111111116 | E49: 13.8 | F49: Mpc | H49: 669004 | I49: =_xlfn.IFS(F49="Mpc",E49*$O$1,F49="kpc",E49*$S$1,F49="pc",E49*$W$1,F49="Lj",E49,E49="",0) -> 45009580 | J49: =AVERAGEIFS(I:I,A:A,A49) -> 43729416 | K49: =(I49/J49-1)*100 -> 2.927466 | L49: =IF(K49>50,"Groesser50",IF(K49<-50,"Kleiner -50","OK")) -> OK
A50: ESO 358-51 | B50: EmG | C50: 55.3858625 | D50: -34.888336111111116 | E50: 14.3 | F50: Mpc | H50: 669004 | I50: =_xlfn.IFS(F50="Mpc",E50*$O$1,F50="kpc",E50*$S$1,F50="pc",E50*$W$1,F50="Lj",E50,E50="",0) -> 46640362 | J50: =AVERAGEIFS(I:I,A:A,A50) -> 43729416 | K50: =(I50/J50-1)*100 -> 6.656722 | L50: =IF(K50>50,"Groesser50",IF(K50<-50,"Kleiner -50","OK")) -> OK
A51: ESO 358-51 | B51: EmG | C51: 55.3858625 | D51: -34.888336111111116 | E51: 12.59 | F51: Mpc | H51: 669004 | I51: =_xlfn.IFS(F51="Mpc",E51*$O$1,F51="kpc",E51*$S$1,F51="pc",E51*$W$1,F51="Lj",E51,E51="",0) -> 41063088 | J51: =AVERAGEIFS(I:I,A:A,A51) -> 43729416 | K51: =(I51/J51-1)*100 -> -6.0973336 | L51: =IF(K51>50,"Groesser50",IF(K51<-50,"Kleiner -50","OK")) -> OK
...

Sheet No_duplicates
A1: id
A2: ACO 262
A3: ACO 347
A4: ACO 3202
A5: ACO 3565
A6: ACO 3581
A7: ACO 3656
A8: ACO 3698
A9: ACO 3742
A10: AM 1321-304
A11: Dwingeloo 1
A12: Dwingeloo 2
... A880: Luhman 16

Sheet preperation
A1: id | B1: otype | C1: ra | D1: dec | E1: distLj_mean | F1: V
A2: ACO 262 | B2: =VLOOKUP(A2,Objects_prepared!A:J,2,FALSE) -> ClG | C2: =VLOOKUP(A2,Objects_prepared!A:J,3,FALSE) -> 28.21 | D2: =VLOOKUP(A2,Objects_prepared!A:J,4,FALSE) -> 36.14611111111111 | E2: =VLOOKUP(A2,Objects_prepared!A:J,10,FALSE) -> 200000000 | F2: =VLOOKUP(A2,Objects_prepared!A:I,7,FALSE) -> 0
A3: ACO 347 | B3: =VLOOKUP(A3,Objects_prepared!A:J,2,FALSE) -> ClG | C3: =VLOOKUP(A3,Objects_prepared!A:J,3,FALSE) -> 36.45833333333333 | D3: =VLOOKUP(A3,Objects_prepared!A:J,4,FALSE) -> 41.875 | E3: =VLOOKUP(A3,Objects_prepared!A:J,10,FALSE) -> 250000000 | F3: =VLOOKUP(A3,Objects_prepared!A:I,7,FALSE) -> 0
A4: ACO 3202 | B4: =VLOOKUP(A4,Objects_prepared!A:J,2,FALSE) -> ClG | C4: =VLOOKUP(A4,Objects_prepared!A:J,3,FALSE) -> 60.05833333333333 | D4: =VLOOKUP(A4,Objects_prepared!A:J,4,FALSE) -> -53.66 | E4: =VLOOKUP(A4,Objects_prepared!A:J,10,FALSE) -> 920000000 | F4: =VLOOKUP(A4,Objects_prepared!A:I,7,FALSE) -> 0
A5: ACO 3565 | B5: =VLOOKUP(A5,Objects_prepared!A:J,2,FALSE) -> ClG | C5: =VLOOKUP(A5,Objects_prepared!A:J,3,FALSE) -> 204.1625 | D5: =VLOOKUP(A5,Objects_prepared!A:J,4,FALSE) -> -33.97166666666667 | E5: =VLOOKUP(A5,Objects_prepared!A:J,10,FALSE) -> 161000000 | F5: =VLOOKUP(A5,Objects_prepared!A:I,7,FALSE) -> 0
A6: ACO 3581 | B6: =VLOOKUP(A6,Objects_prepared!A:J,2,FALSE) -> ClG | C6: =VLOOKUP(A6,Objects_prepared!A:J,3,FALSE) -> 211.87416666666667 | D6: =VLOOKUP(A6,Objects_prepared!A:J,4,FALSE) -> -27.017777777777777 | E6: =VLOOKUP(A6,Objects_prepared!A:J,10,FALSE) -> 278000000 | F6: =VLOOKUP(A6,Objects_prepared!A:I,7,FALSE) -> 0
A7: ACO 3656 | B7: =VLOOKUP(A7,Objects_prepared!A:J,2,FALSE) -> GrG | C7: =VLOOKUP(A7,Objects_prepared!A:J,3,FALSE) -> 299.7245833333333 | D7: =VLOOKUP(A7,Objects_prepared!A:J,4,FALSE) -> -38.34527777777778 | E7: =VLOOKUP(A7,Objects_prepared!A:J,10,FALSE) -> 269000000 | F7: =VLOOKUP(A7,Objects_prepared!A:I,7,FALSE) -> 0
A8: ACO 3698 | B8: =VLOOKUP(A8,Objects_prepared!A:J,2,FALSE) -> ClG | C8: =VLOOKUP(A8,Objects_prepared!A:J,3,FALSE) -> 308.9916666666667 | D8: =VLOOKUP(A8,Objects_prepared!A:J,4,FALSE) -> -25.276666666666667 | E8: =VLOOKUP(A8,Objects_prepared!A:J,10,FALSE) -> 264000000 | F8: =VLOOKUP(A8,Objects_prepared!A:I,7,FALSE) -> 0
A9: ACO 3742 | B9: =VLOOKUP(A9,Objects_prepared!A:J,2,FALSE) -> ClG | C9: =VLOOKUP(A9,Objects_prepared!A:J,3,FALSE) -> 316.67083333333335 | D9: =VLOOKUP(A9,Objects_prepared!A:J,4,FALSE) -> -47.14833333333333 | E9: =VLOOKUP(A9,Objects_prepared!A:J,10,FALSE) -> 2.2830946e+08 | F9: =VLOOKUP(A9,Objects_prepared!A:I,7,FALSE) -> 0
A10: AM 1321-304 | B10: =VLOOKUP(A10,Objects_prepared!A:J,2,FALSE) -> GiC | C10: =VLOOKUP(A10,Objects_prepared!A:J,3,FALSE) -> 201.15095999999997 | D10: =VLOOKUP(A10,Objects_prepared!A:J,4,FALSE) -> -30.971809999999994 | E10: =VLOOKUP(A10,Objects_prepared!A:J,10,FALSE) -> 15519608 | F10: =VLOOKUP(A10,Objects_prepared!A:I,7,FALSE) -> 0
A11: Dwingeloo 1 | B11: =VLOOKUP(A11,Objects_prepared!A:J,2,FALSE) -> GiG | C11: =VLOOKUP(A11,Objects_prepared!A:J,3,FALSE) -> 44.21514973175001 | D11: =VLOOKUP(A11,Objects_prepared!A:J,4,FALSE) -> 58.91170468878 | E11: =VLOOKUP(A11,Objects_prepared!A:J,10,FALSE) -> 13502874 | F11: =VLOOKUP(A11,Objects_prepared!A:I,7,FALSE) -> 0
A12: Dwingeloo 2 | B12: =VLOOKUP(A12,Objects_prepared!A:J,2,FALSE) -> G | C12: =VLOOKUP(A12,Objects_prepared!A:J,3,FALSE) -> 43.535291666666666 | D12: =VLOOKUP(A12,Objects_prepared!A:J,4,FALSE) -> 59.00530555555556 | E12: =VLOOKUP(A12,Objects_prepared!A:J,10,FALSE) -> 11350242 | F12: =VLOOKUP(A12,Objects_prepared!A:I,7,FALSE) -> 0
A13: ESO 118-19 | B13: =VLOOKUP(A13,Objects_prepared!A:J,2,FALSE) -> EmG | C13: =VLOOKUP(A13,Objects_prepared!A:J,3,FALSE) -> 64.74794232692 | D13: =VLOOKUP(A13,Objects_prepared!A:J,4,FALSE) -> -58.25753017908001 | E13: =VLOOKUP(A13,Objects_prepared!A:J,10,FALSE) -> 0 | F13: =VLOOKUP(A13,Objects_prepared!A:I,7,FALSE) -> 15.51
... A880: Luhman 16 | B880: =VLOOKUP(A880,Objects_prepared!A:J,2,FALSE) -> ** | C880: =VLOOKUP(A880,Objects_prepared!A:J,3,FALSE) -> 162.32881400000002 | D880: =VLOOKUP(A880,Objects_prepared!A:J,4,FALSE) -> -53.319466000000006 | E880: =VLOOKUP(A880,Objects_prepared!A:J,10,FALSE) -> 6.5231276 | F880: =VLOOKUP(A880,Objects_prepared!A:I,7,FALSE) -> 16.2

Sheet Consolidation
A1: id | B1: otype | C1: ra | D1: dec | E1: distLj_mean | F1: V
A2: ACO 262 | B2: ClG | C2: 28.21 | D2: 36.14611111111111 | E2: 200000000 | F2: 0
A3: ACO 347 | B3: ClG | C3: 36.45833333333333 | D3: 41.875 | E3: 250000000 | F3: 0
A4: ACO 3202 | B4: ClG | C4: 60.05833333333333 | D4: -53.66 | E4: 920000000 | F4: 0
A5: ACO 3565 | B5: ClG | C5: 204.1625 | D5: -33.97166666666667 | E5: 161000000 | F5: 0
A6: ACO 3581 | B6: ClG | C6: 211.87416666666667 | D6: -27.017777777777777 | E6: 278000000 | F6: 0
A7: ACO 3656 | B7: GrG | C7: 299.7245833333333 | D7: -38.34527777777778 | E7: 269000000 | F7: 0
A8: ACO 3698 | B8: ClG | C8: 308.9916666666667 | D8: -25.276666666666667 | E8: 264000000 | F8: 0
A9: ACO 3742 | B9: ClG | C9: 316.67083333333335 | D9: -47.14833333333333 | E9: 2.2830946e+08 | F9: 0
A10: AM 1321-304 | B10: GiC | C10: 201.15095999999997 | D10: -30.971809999999994 | E10: 15519608 | F10: 0
A11: Dwingeloo 1 | B11: GiG | C11: 44.21514973175001 | D11: 58.91170468878 | E11: 13502874 | F11: 0
A12: Dwingeloo 2 | B12: G | C12: 43.535291666666666 | D12: 59.00530555555556 | E12: 11350242 | F12: 0
A13: ESO 118-19 | B13: EmG | C13: 64.74794232692 | D13: -58.25753017908001 | E13: 0 | F13: 15.51
A14: ESO 157-30 | B14: GiG | C14: 66.88600968933 | D14: -54.19679156960999 | E14: 0 | F14: 0
A15: ESO 157-47 | B15: AG? | C15: 69.82972 | D15: -54.21151 | E15: 70094267 | F15: 0
A16: ESO 157-49 | B16: GiG | C16: 69.90367916666668 | D16: -53.01265 | E16: 69777374 | F16: 0
A17: ESO 302-14 | B17: GiG | C17: 57.92042000000001 | D17: -38.45222 | E17: 35877202 | F17: 0
A18: ESO 302-9 | B18: EmG | C18: 56.89217 | D18: -38.57653 | E18: 60241083 | F18: 0
A19: ESO 357-12 | B19: GiC | C19: 49.2221475 | D19: -35.541411399999994 | E19: 61911004 | F19: 0
A20: ESO 357-7 | B20: EmG | C20: 47.5981078 | D20: -33.1535773 | E20: 53391799 | F20: 0
A21: ESO 358-10 | B21: GiG | C21: 52.43027 | D21: -33.55694 | E21: 0 | F21: 0
A22: ESO 358-50 | B22: GiG | C22: 55.26503265065 | D22: -33.77924934877 | E22: 61822044 | F22: 0
A23: ESO 358-51 | B23: EmG | C23: 55.3858625 | D23: -34.888336111111116 | E23: 43729416 | F23: 0
A24: ESO 358-60 | B24: GiC | C24: 56.30059 | D24: -35.570910000000005 | E24: 44813886 | F24: 0
A25: ESO 358-9 | B25: GiG | C25: 52.20299166666667 | D25: -35.17815833333332 | E25: 62964040 | F25: 0
... A39: IC 1070 | B39: GiP | C39: 223.46368048481997 | D39: 3.48462931384 | E39: 83822189 | F39: 0
A40: IC 1574 | B40: AG? | C40: 10.7659 | D40: -22.24688 | E40: 16238511 | F40: 14.35
A41: IC 1613 | B41: GiC | C41: 16.2016962 | D41: 2.1194958999999995 | E41: 2390824.1 | F41: 10.01
A42: IC 1898 | B42: Sy2 | C42: 47.57945833333333 | D42: -22.406019444444443 | E42: 63395481 | F42: 0
A43: IC 1913 | B43: EmG | C43: 49.89407500000001 | D43: -32.465113888888894 | E43: 67193650 | F43: 0
A44: IC 1919 | B44: GiG | C44: 51.50922190699 | D44: -32.89453438438 | E44: 59996466 | F44: 0
A45: IC 1952 | B45: Sy2 | C45: 53.36116666666666 | D45: -23.712788888888884 | E45: 73151440 | F45: 0
A46: IC 1953 | B46: GiG | C46: 53.42452083333333 | D46: -21.47861944444444 | E46: 81669557 | F46: 0
A47: IC 1993 | B47: GiG | C47: 56.77015379321 | D47: -33.70996611048 | E47: 44911733 | F47: 0
A48: IC 2006 | B48: EmG | C48: 58.61859507635 | D48: -35.96713156181001 | E48: 62942745 | F48: 0
A49: IC 2032 | B49: EmG | C49: 61.76266 | D49: -55.32383 | E49: 46640362 | F49: 14.73
A50: IC 2038 | B50: GiP | C50: 62.22398748881001 | D50: -55.9893828178 | E50: 24000000 | F50: 0
A51: IC 2049 | B51: AG? | C51: 63.01783 | D51: -58.557 | E51: 54468115 | F51: 14.74
A52: IC 2056 | B52: GiG | C52: 64.10212629247 | D52: -60.20678268484001 | E52: 47520984 | F52: 0
A53: IC 2058 | B53: EmG | C53: 64.47655023026 | D53: -55.932705095100005 | E53: 56849057 | F53: 0
...
